Workbook

Sheet Index
A1: ='Historical '!C1 -> Neogen Chemicals Limited
A2: Financial Model
B4: Inputs
C6: Historical Financial Statement
C7: Assumptions
C8: Market Data
C9: Revenue & Cost buildup
B11: Calculation & Analysis
C12: Income Statement
C13: Balance Sheet
C14: Cash Flow Statement
C15: Working Capital
C16: Depreciation Schedule
C17: Debt Schedule
C18: WACC
C19: Beta
C20: Sensitivity Analysis
B22: Outputs
C23: DCF Model
C24: Ratio Analysis
C25: Comparables Analysis
C26: Valuation Summary

Sheet Assumptions
B1: =Scenarios!A1 -> Neogen Chemicals Limited
B3: Assumptions
B5: Company Description | D5: Neogen Chemicals Limited
B6: ISIN Code | D6: INE136S01016
B7: Sector Name | D7: Chemicals
B8: Industry | D8: Specialty Chemicals
B9: Exchange Name | D9: BSE: 542665, NSE: NEOGEN
B10: Website | D10: https://neogenchem.com/
B11: Company Description | D11: Neogen Chemicals Limited is an India-based specialty chemicals manufacturer with strong expertise in bromine-based and lithium-based chemistries. The company supplies high-value chemical solutions to industries such as pharmaceuticals, agrochemicals, electronics, polymers, water treatment, and energy storage. Neogen has a growing global presence with exports to 30+ countries, supported by advanced manufacturing facilities in India and strong R&D capabilities. The company is also expanding its lithium-ion battery materials business to support the rapidly growing electric vehicle (EV) ecosystem.
B12: Current Market Price | D12: 1669.3
B14: Company data
B15: Particulars | D15: Amount
B16: No of Outstanding shares | C16: No's | D16: 26381674
B17: Face Value per share | C17: Rs. | D17: 10
B18: Current Market Price | C18: Rs. | D18: =D12 -> 1669.3
B19: Market Capitalisation | C19: INR in cr | D19: =D16*D18 -> 4.4038928e+10
B22: Company Export data
B23: Year | D23: Revenue in Cr
B24: 2021 | D24: =Model!H24 -> 336.41
B25: =B24+1 -> 2022 | D25: =Model!I24 -> 487.25
B26: =B25+1 -> 2023 | D26: =Model!J24 -> 686.18
B27: =B26+1 -> 2024 | D27: =Model!K24 -> 690.67
B28: =B27+1 -> 2025 | D28: =Model!L24 -> 777.56
B30: Headings | C30: Reference | D30: Assumptions
B31: Revenue & Cost Buildup | C31: M8:V8 | D31: For FY2026, revenue growth is assumed at 7.0% based on management guidance, industry outlook, and analyst expectations. The bull case is derived by adding 5.0% to the base case growth, resulting in 12.0%, while the bear case is derived by reducing 5.0%, resulting in 2.0%. In all scenarios, the growth rate is gradually tapered by 6.0% over the forecast period, reaching approximately 4.0% by FY2035, reflecting a conservative long-term normalization approach.
C32: M9:V9 M10:V10 M11:V11 | D32: COGS, Salaries & Benefits and Other SG&A Expenses is taken as average of last 5 audited years and assumed to be remain constatnt throughout the projection period.
C33: M12:V12 | D33: The FY2025 depreciation rate of 3.6% is taken as the base. For FY2026, the rate is increased by 0.5% to 4.1%, and thereafter, it is assumed to increase by 0.5% every two years over the forecast period, reflecting a gradual rise in asset base and capital intensity.
C34: M13:V13 | D34: Interest rate was calculated as average of last 4 audited years which is coming 12% and then assumed to be remain same throughout the forecasted period.
C35: M14:V14 | D35: Other income was computed by taking the average of historical years and is assumed to remain constant throughout the projected period.
C36: M15:V15 | D36: The FY2025 effective tax rate of 30.6% is taken as the base. For FY2026, the rate is normalized to 30.76%, increasing by 0.20%. Thereafter, the rate is assumed to increase by 0.20% every two years over the forecast period, reflecting a gradual rise in line with prevailing corporate tax trends in India.
C37: M16:V16 | D37: Dividend Payout is assumed as average of the last 5 years which is coming closer to 15.31% which is assumed to be the dividend payments throughout the forecast period
C38: M17:V17, M18:V18, M19:V19 | D38: Trade Receivables, Inventory, and Trade Payables were calculated by determining the DSO, DIO, and DPO for all five audited years. The average of these metrics was then taken and assumed to remain constant during the forecasted years. These constant ratios were subsequently multiplied by the Revenue and Inventory of the respective forecast years to estimate the values.
C39: M20:V20 | D39: Capital Expenditure (Capex) has been estimated using the average of the last four historical years to normalize fluctuations. For the projected period, Capex is assumed to grow at a steady rate of 0.5% annually, reflecting stable operations and ongoing maintenance requirements. This represents a conservative and realistic assumption.
B40: Balance Sheet | C40: M42:V42 | D40: Cash and Cash equivalents are taken from the closing cash balance of cash flow statements.
C41: M43:V43 | D41: Bank deposits are based on the historical trend of relatively low balances in prior years. Considering the company’s operational cash utilization, it is assumed that no significant surplus funds will be maintained in bank deposits going forward, and hence the balance is projected to remain minimal/negligible throughout the forecast period.
C42: M46:V46 M50:V50 M53:V53 M51:V51 M57:V57 | D42: Other Current Assets, Financial Assets, Other Non-Current Assets, Other Current Liability and Other Non-Current Liability and taken from the last audited year i.e 2025 and assumed to be remain constant throughout the forecasted period i.e from (2026-35).
B43: Shareholder's Equity | C43: M65:V65 | D43: Shareholders’ Equity is projected based on the retention of earnings over the forecast period , with no major changes in equity structure such as fresh equity issuance or buybacks. The increase in equity is primarily driven by internal accruals (retained earnings), reflecting a stable growth trajectory of the company while maintaining a consistent capital structure.
B44: Supporting Schedules | C44: M118:V118 | D44: Debt Issuance/Repayment is assumed to be Zero for thr forecasted years.

Sheet Historical 
C1: =Assumptions!D5 -> Neogen Chemicals Limited
C2: Historical Financial Information | N2: (Rs. in Crores)
C3: Blue- Hard Coded, Black- Calculation & Green- Linkages
A4: # | B4: # | C4: INCOME STATEMENT | J4: 2021 | K4: =J4+1 -> 2022 | L4: =K4+1 -> 2023 | M4: =L4+1 -> 2024 | N4: =M4+1 -> 2025
C5: I. Income
E6: (a) Revenue from operations | J6: 336.41 | K6: 487.25 | L6: 686.18 | M6: 690.67 | N6: 777.56
E7: (b) Other income | J7: 0.14 | K7: 1.07 | L7: 4.45 | M7: 7.47 | N7: 4.01
E8: Total Income | J8: =SUM(J6:J7) -> 336.55 | K8: =SUM(K6:K7) -> 488.32 | L8: =SUM(L6:L7) -> 690.63 | M8: =SUM(M6:M7) -> 698.14 | N8: =SUM(N6:N7) -> 781.57
C9: II. Expenses
E10: (a) Cost of materials consumed | J10: 180.76 | K10: 343.77 | L10: 485.26 | M10: 474.59 | N10: 506.08
E11: (b) Changes in inventories of finished goods, work-in-progress and stock-in-trade | J11: 16.87 | K11: -68.8 | L11: -96.75 | M11: -92.1 | N11: -83.02
E12: (c) Employee benefits expense | J12: 20.07 | K12: 31.5 | L12: 46.82 | M12: 62 | N12: 64.84
E13: (d) Finance costs | J13: 13.77 | K13: 19.08 | L13: 28.94 | M13: 42.06 | N13: 48.5
E14: (e) Depreciation and amortisation expenses | J14: 6.9 | K14: 11.69 | L14: 16.2 | M14: 22.87 | N14: 27.79
E15: (f) Other expense | J15: 54.35 | K15: 94.19 | L15: 139.23 | M15: 136.13 | N15: 153.34
E16: Total Expenses | J16: =SUM(J10:J15) -> 292.72 | K16: =SUM(K10:K15) -> 431.43 | L16: =SUM(L10:L15) -> 619.7 | M16: =SUM(M10:M15) -> 645.55 | N16: =SUM(N10:N15) -> 717.53
E17: Profit /(loss) before share of profit of investment accounted for using equity method and taxes (I-II) | J17: =J8-J16 -> 43.83 | K17: =K8-K16 -> 56.89 | L17: =L8-L16 -> 70.93 | M17: =M8-M16 -> 52.59 | N17: =N8-N16 -> 64.04
E18: Share of Profit/(Loss) of investments accounted for using equity method | J18: 0.38 | K18: 0.18 | L18: 0.1 | M18: 0.18 | N18: 0.2
E19: Exceptional items | J19: 0 | K19: 0 | L19: 0 | M19: 0 | N19: -14.08
C20: III. Profit/(loss) before taxes | J20: =SUM(J17:J18) -> 44.21 | K20: =SUM(K17:K18) -> 57.07 | L20: =L8-L16+L18 -> 71.03 | M20: =M8-M16+M18 -> 52.77 | N20: =N8-N16+N18+N19 -> 50.16
C21: IV. Income tax
E22: 1. Current Tax | J22: 10.37 | K22: 9.87 | L22: 12.76 | M22: 12.24 | N22: 20.54
E23: 2. Deferred Tax | J23: 2.51 | K23: 2.57 | L23: 8.3 | M23: 4.88 | N23: -5.21
E24: Total Tax Expense | J24: =SUM(J22:J23) -> 12.88 | K24: =SUM(K22:K23) -> 12.44 | L24: =SUM(L22:L23) -> 21.06 | M24: =SUM(M22:M23) -> 17.12 | N24: =SUM(N22:N23) -> 15.33
C25: V. Profit for the year (III - IV) | J25: =J20-J24 -> 31.33 | K25: =K20-K24 -> 44.63 | L25: =L20-L24 -> 49.97 | M25: =M20-M24 -> 35.65 | N25: =N20-N24 -> 34.83
A27: # | B27: # | C27: BALANCE SHEET
C28: ASSETS
C29: (1) Non-current assets
D30: (a) Property, plant and equipment | J30: 121.53 | K30: 281.78 | L30: 339.32 | M30: 480.37 | N30: 373.64
D31: (b) Right of use assets | J31: 4.85 | K31: 3.19 | L31: 6.72 | M31: 14.1 | N31: 29.27
D32: (c) Capital work-in-progress | J32: 114.65 | K32: 10.62 | L32: 35.84 | M32: 108.91 | N32: 156.19
D33: (d) Intangible assets | J33: 0.33 | K33: 0.16 | L33: 1.41 | M33: 1.15 | N33: 0.94
D34: (e) Financial assets
E35: (i) Investments | J35: 0.75 | K35: 0.97 | L35: 0.75 | M35: 0.45 | N35: 0.45
E36: (ii) Other financial assets | J36: 7.34 | K36: 8.48 | L36: 7.47 | M36: 10.78 | N36: 13.84
E37: (iii)Loans | J37: - | K37: - | L37: - | M37: - | N37: 0.27
D38: (f) Other non-current assets | J38: - | K38: - | L38: - | M38: 61.89 | N38: 172.88
D39: (g) Non-current tax assets (net) | J39: 2.35 | K39: 1.6 | L39: 6.46 | M39: 0.09 | N39: -
C40: Total Non-current Assets | J40: =SUM(J30:J39) -> 251.8 | K40: =SUM(K30:K39) -> 306.8 | L40: =SUM(L30:L39) -> 397.97 | M40: =SUM(M30:M39) -> 677.74 | N40: =SUM(N30:N39) -> 747.48
C41: (2) Current Assets
...

Sheet Model
A1: ='Historical '!C1 -> Neogen Chemicals Limited | H1: Historical Period | M1: Forecast Period
A2: Financial Statements & DCF Analysis | H2: 2021 | I2: =H2+1 -> 2022 | J2: =I2+1 -> 2023 | K2: =J2+1 -> 2024 | L2: =K2+1 -> 2025 | M2: =L2+1 -> 2026 | N2: =M2+1 -> 2027 | O2: =N2+1 -> 2028 | P2: =O2+1 -> 2029 | ... V2: =U2+1 -> 2035
D3: Master Check | H3: =IF(H68=0,"OK","ERROR") -> OK | I3: =IF(I68=0,"OK","ERROR") -> OK | J3: =IF(J68=0,"OK","ERROR") -> OK | K3: =IF(K68=0,"OK","ERROR") -> OK | L3: =IF(L68=0,"OK","ERROR") -> OK | M3: =IF(M68=0,"OK","ERROR") -> OK | N3: =IF(N68=0,"OK","ERROR") -> OK | O3: =IF(O68=0,"OK","ERROR") -> OK | ... V3: =IF(V68=0,"OK","ERROR") -> OK
A4: Blue- Hard Coded, Black- Calculation & Green- Linkages | G4: 1
A5: Revenue & Cost Buildup
B7: LIVE SCENARIO | E7: Base Case | F7: Units | G7: =IF(E7=Scenarios!D5,1,IF(Model!E7=Scenarios!D6,2,3)) -> 1
B8: Revenue Growth | F8: % | H8: - | I8: =I24/H24-1 -> 0.44838144 | J8: =J24/I24-1 -> 0.40827091 | K8: =K24/J24-1 -> 0.0065434726 | L8: =L24/K24-1 -> 0.12580538 | M8: =CHOOSE($G$7,Scenarios!H5,Scenarios!H6,Scenarios!H7) -> 0.07 | N8: =CHOOSE($G$7,Scenarios!I5,Scenarios!I6,Scenarios!I7) -> 0.0658 | O8: =CHOOSE($G$7,Scenarios!J5,Scenarios!J6,Scenarios!J7) -> 0.061852 | P8: =CHOOSE($G$7,Scenarios!K5,Scenarios!K6,Scenarios!K7) -> 0.05814088 | Q8: =CHOOSE($G$7,Scenarios!L5,Scenarios!L6,Scenarios!L7) -> 0.054652427 | R8: =CHOOSE($G$7,Scenarios!M5,Scenarios!M6,Scenarios!M7) -> 0.051373282 | S8: =CHOOSE($G$7,Scenarios!N5,Scenarios!N6,Scenarios!N7) -> 0.048290885 | T8: =CHOOSE($G$7,Scenarios!O5,Scenarios!O6,Scenarios!O7) -> 0.045393432 | ... V8: =CHOOSE($G$7,Scenarios!Q5,Scenarios!Q6,Scenarios!Q7) -> 0.040109636
B9: Cost of Goods Sold (% of Revenue) | F9: % | H9: =-Model!H25/Model!H24 -> 0.58746767 | I9: =-Model!I25/Model!I24 -> 0.56433043 | J9: =-Model!J25/Model!J24 -> 0.56619254 | K9: =-Model!K25/Model!K24 -> 0.55379559 | L9: =-Model!L25/Model!L24 -> 0.54408663 | M9: =+AVERAGE(H9:L9) -> 0.56317457 | N9: =M9 -> 0.56317457 | O9: =N9 -> 0.56317457 | P9: =O9 -> 0.56317457 | Q9: =P9 -> 0.56317457 | R9: =Q9 -> 0.56317457 | S9: =R9 -> 0.56317457 | T9: =S9 -> 0.56317457 | U9: =T9 -> 0.56317457 | V9: =U9 -> 0.56317457
B10: Salaries and benefits (% of Revenue) | F10: % | H10: =-H28/H24 -> 0.059659344 | I10: =-I28/I24 -> 0.064648538 | J10: =-J28/J24 -> 0.068232825 | K10: =-K28/K24 -> 0.089767907 | L10: =-L28/L24 -> 0.083389063 | M10: =AVERAGE(H10:L10) -> 0.073139535 | N10: =M10 -> 0.073139535 | O10: =N10 -> 0.073139535 | P10: =O10 -> 0.073139535 | Q10: =P10 -> 0.073139535 | R10: =Q10 -> 0.073139535 | S10: =R10 -> 0.073139535 | T10: =S10 -> 0.073139535 | U10: =T10 -> 0.073139535 | V10: =U10 -> 0.073139535
B11: Other SG&A Expenses (% of Revenue) | F11: % | H11: =-H29/H24 -> 0.16155881 | I11: =-I29/I24 -> 0.19330939 | J11: =-J29/J24 -> 0.20290594 | K11: =-K29/K24 -> 0.19709847 | L11: =-L29/L24 -> 0.19720665 | M11: =AVERAGE(H11:L11) -> 0.19041585 | N11: =M11 -> 0.19041585 | O11: =N11 -> 0.19041585 | P11: =O11 -> 0.19041585 | Q11: =P11 -> 0.19041585 | R11: =Q11 -> 0.19041585 | S11: =R11 -> 0.19041585 | T11: =S11 -> 0.19041585 | U11: =T11 -> 0.19041585 | V11: =U11 -> 0.19041585
B12: Depreciation & Amortization Expenses (% of PP&E) | F12: % | H12: 0 | I12: =-I31/I24 -> 0.023991791 | J12: =-J31/J24 -> 0.023608966 | K12: =-K31/K24 -> 0.033112775 | L12: =-L31/L24 -> 0.035740007 | M12: =L12+0.5% -> 0.040740007 | N12: =M12 -> 0.040740007 | O12: =N12 -> 0.040740007 | P12: =O12+0.5% -> 0.045740007 | Q12: =P12 -> 0.045740007 | R12: =Q12 -> 0.045740007 | S12: =R12+0.5% -> 0.050740007 | T12: =S12 -> 0.050740007 | U12: =T12 -> 0.050740007 | V12: =U12+0.5% -> 0.055740007
B13: Interest (% of Debt) | F13: % | H13: 0 | I13: =-I33/I118 -> 0.09450691 | J13: =-J33/J118 -> 0.1463686 | K13: =-K33/K118 -> 0.11612048 | L13: =-L33/L118 -> 0.12324346 | M13: =AVERAGE(I13:L13) -> 0.12005986 | N13: =M13 -> 0.12005986 | O13: =N13 -> 0.12005986 | P13: =O13 -> 0.12005986 | Q13: =P13 -> 0.12005986 | R13: =Q13 -> 0.12005986 | S13: =R13 -> 0.12005986 | T13: =S13 -> 0.12005986 | U13: =T13 -> 0.12005986 | V13: =U13 -> 0.12005986
B14: Other Income (Expenses) (% of Revenue) | F14: % | H14: =H34/H24 -> 0.0015457329 | I14: =I34/I24 -> 0.0025654182 | J14: =J34/J24 -> 0.0066309132 | K14: =K34/K24 -> 0.011076201 | L14: =-L34/L24 -> 0.012693554 | M14: =AVERAGE(H14:L14) -> 0.006902364 | N14: =M14 -> 0.006902364 | O14: =N14 -> 0.006902364 | P14: =O14 -> 0.006902364 | Q14: =P14 -> 0.006902364 | R14: =Q14 -> 0.006902364 | S14: =R14 -> 0.006902364 | T14: =S14 -> 0.006902364 | U14: =T14 -> 0.006902364 | V14: =U14 -> 0.006902364
B15: Effective Tax Rate (% of Earnings before Tax) | F15: % | H15: =-H36/H35 -> 0.2913368 | I15: =-I36/I35 -> 0.21797792 | J15: =-J36/J35 -> 0.29649444 | K15: =-K36/K35 -> 0.32442676 | L15: =-L36/L35 -> 0.30562201 | M15: =L15+0.2% -> 0.30762201 | N15: =M15 -> 0.30762201 | O15: =N15 -> 0.30762201 | P15: =O15+0.2% -> 0.30962201 | Q15: =P15 -> 0.30962201 | R15: =Q15 -> 0.30962201 | S15: =R15+0.2% -> 0.31162201 | T15: =S15 -> 0.31162201 | U15: =T15 -> 0.31162201 | V15: =U15+0.2% -> 0.31362201
B16: Dividends Payout | H16: =-H91/H37 -> 0.14905841 | I16: =-I91/I37 -> 0.11763388 | J16: =-J91/J37 -> 0.13728237 | K16: =-K91/K37 -> 0.20981767 | L16: =-L91/L37 -> 0.15159345 | M16: =AVERAGE(H16:L16) -> 0.15307716 | N16: =M16 -> 0.15307716 | O16: =N16 -> 0.15307716 | P16: =O16 -> 0.15307716 | Q16: =P16 -> 0.15307716 | R16: =Q16 -> 0.15307716 | S16: =R16 -> 0.15307716 | T16: =S16 -> 0.15307716 | U16: =T16 -> 0.15307716 | V16: =U16 -> 0.15307716
B17: Accounts Receivable | F17: Days | H17: =H44/H24*365 -> 85.225618 | I17: =I44/I24*365 -> 82.02668 | J17: =J44/J24*365 -> 94.353814 | K17: =K44/K24*365 -> 148.86538 | L17: =L44/L24*365 -> 93.986702 | M17: =AVERAGE(H17:L17) -> 100.89164 | N17: =M17 -> 100.89164 | O17: =N17 -> 100.89164 | P17: =O17 -> 100.89164 | Q17: =P17 -> 100.89164 | R17: =Q17 -> 100.89164 | S17: =R17 -> 100.89164 | T17: =S17 -> 100.89164 | U17: =T17 -> 100.89164 | V17: =U17 -> 100.89164
B18: Inventory | F18: Days | H18: =-H45/H25*365 -> 210.60036 | I18: =-I45/I25*365 -> 258.30218 | J18: =-J45/J25*365 -> 275.24144 | K18: =-K45/K25*365 -> 364.95229 | L18: =-L45/L25*365 -> 266.70555 | M18: =+AVERAGE(H18:L18) -> 275.16036 | N18: =M18 -> 275.16036 | O18: =N18 -> 275.16036 | P18: =O18 -> 275.16036 | Q18: =P18 -> 275.16036 | R18: =Q18 -> 275.16036 | S18: =R18 -> 275.16036 | T18: =S18 -> 275.16036 | U18: =T18 -> 275.16036 | V18: =U18 -> 275.16036
B19: Accounts Payable | F19: Days | H19: =-H56/H25*365 -> 122.0422 | I19: =-I56/I25*365 -> 131.25505 | J19: =-J56/J25*365 -> 147.07665 | K19: =-K56/K25*365 -> 137.98792 | L19: =-L56/L25*365 -> 227.07027 | M19: =+AVERAGE(H19:L19) -> 153.08642 | N19: =M19 -> 153.08642 | O19: =N19 -> 153.08642 | P19: =O19 -> 153.08642 | Q19: =P19 -> 153.08642 | R19: =Q19 -> 153.08642 | S19: =R19 -> 153.08642 | T19: =S19 -> 153.08642 | U19: =T19 -> 153.08642 | V19: =U19 -> 153.08642
B20: Capital Asset turnover | H20: =+H24/H48 -> 1.3957184 | I20: =+I24/I48 -> 1.6483981 | J20: =+J24/J48 -> 1.7968472 | K20: =+K24/K48 -> 1.1446684 | L20: =+L24/L48 -> 1.3907351 | M20: =+L20+0.3 -> 1.6907351 | N20: =+M20+0.3 -> 1.9907351 | O20: =+N20+0.3 -> 2.2907351 | P20: =+O20+0.3 -> 2.5907351 | Q20: =+P20+0.3 -> 2.8907351 | R20: =+Q20+0.3 -> 3.1907351 | S20: =+R20+0.3 -> 3.4907351 | T20: =+S20+0.3 -> 3.7907351 | ... V20: =+U20+0.3 -> 4.3907351
A22: Income Statement
B23: INCOME
D24: Revenue | F24: ₹ Cr | H24: ='Historical '!J6 -> 336.41 | I24: ='Historical '!K6 -> 487.25 | J24: ='Historical '!L6 -> 686.18 | K24: ='Historical '!M6 -> 690.67 | L24: ='Historical '!N6 -> 777.56 | M24: =L24*(1+M8) -> 831.9892 | N24: =M24*(1+N8) -> 886.73409 | O24: =N24*(1+O8) -> 941.58037 | P24: =O24*(1+P8) -> 996.32468 | Q24: =P24*(1+Q8) -> 1050.7762 | R24: =Q24*(1+R8) -> 1104.7581 | S24: =R24*(1+S8) -> 1158.1078 | T24: =S24*(1+T8) -> 1210.6783 | ... V24: =U24*(1+V8) -> 1312.9696
D25: Cost of Good Sold (COGS) | F25: ₹ Cr | H25: =-SUM('Historical '!J10,'Historical '!J11) -> -197.63 | I25: =-SUM('Historical '!K10,'Historical '!K11) -> -274.97 | J25: =-SUM('Historical '!L10,'Historical '!L11) -> -388.51 | K25: =-SUM('Historical '!M10,'Historical '!M11) -> -382.49 | L25: =-SUM('Historical '!N10,'Historical '!N11) -> -423.06 | M25: =-M24*M9 -> -468.55516 | N25: =-N24*N9 -> -499.38609 | O25: =-O24*O9 -> -530.27412 | P25: =-P24*P9 -> -561.10472 | Q25: =-Q24*Q9 -> -591.77046 | R25: =-R24*R9 -> -622.17165 | S25: =-S24*S9 -> -652.21687 | T25: =-T24*T9 -> -681.82323 | ... V25: =-V24*V9 -> -739.43111
D26: Gross Profit | F26: ₹ Cr | H26: =SUM(H24:H25) -> 138.78 | I26: =SUM(I24:I25) -> 212.28 | J26: =SUM(J24:J25) -> 297.67 | K26: =SUM(K24:K25) -> 308.18 | L26: =SUM(L24:L25) -> 354.5 | M26: =SUM(M24:M25) -> 363.43404 | N26: =SUM(N24:N25) -> 387.348 | O26: =SUM(O24:O25) -> 411.30625 | ... V26: =SUM(V24:V25) -> 573.53852
B27: EXPENSES
D28: Salaries and benefits | F28: ₹ Cr | H28: =-'Historical '!J12 -> -20.07 | I28: =-'Historical '!K12 -> -31.5 | J28: =-'Historical '!L12 -> -46.82 | K28: =-'Historical '!M12 -> -62 | L28: =-'Historical '!N12 -> -64.84 | M28: =-M24*M10 -> -60.851304 | N28: =-N24*N10 -> -64.855319 | O28: =-O24*O10 -> -68.866751 | P28: =-P24*P10 -> -72.870724 | Q28: =-Q24*Q10 -> -76.853286 | R28: =-R24*R10 -> -80.801491 | S28: =-S24*S10 -> -84.703467 | T28: =-T24*T10 -> -88.548448 | ... V28: =-V24*V10 -> -96.029989
D29: Other SG&A Expenses | F29: ₹ Cr | H29: =-'Historical '!J15 -> -54.35 | I29: =-'Historical '!K15 -> -94.19 | J29: =-'Historical '!L15 -> -139.23 | K29: =-'Historical '!M15 -> -136.13 | L29: =-'Historical '!N15 -> -153.34 | M29: =-M24*M11 -> -158.42393 | N29: =-N24*N11 -> -168.84823 | O29: =-O24*O11 -> -179.29183 | P29: =-P24*P11 -> -189.71601 | Q29: =-Q24*Q11 -> -200.08445 | R29: =-R24*R11 -> -210.36345 | S29: =-S24*S11 -> -220.52208 | T29: =-T24*T11 -> -230.53234 | ... V29: =-V24*V11 -> -250.01023
D30: EBITDA | F30: ₹ Cr | H30: =SUM(H26:H29) -> 64.36 | I30: =SUM(I26:I29) -> 86.59 | J30: =SUM(J26:J29) -> 111.62 | K30: =SUM(K26:K29) -> 110.05 | L30: =SUM(L26:L29) -> 136.32 | M30: =SUM(M26:M29) -> 144.1588 | N30: =SUM(N26:N29) -> 153.64445 | O30: =SUM(O26:O29) -> 163.14767 | ... V30: =SUM(V26:V29) -> 227.4983
D31: Depreciation & Amortization Expenses | F31: ₹ Cr | H31: =-'Historical '!J14 -> -6.9 | I31: =-'Historical '!K14 -> -11.69 | J31: =-'Historical '!L14 -> -16.2 | K31: =-'Historical '!M14 -> -22.87 | L31: =-'Historical '!N14 -> -27.79 | M31: =M113 -> -22.777738 | N31: =N113 -> -25.889348 | O31: =O113 -> -28.874395 | P31: =P113 -> -35.633227 | Q31: =Q113 -> -38.5394 | R31: =R113 -> -41.312873 | S31: =S113 -> -48.765106 | T31: =T113 -> -51.323411 | ... V31: =V113 -> -61.581969
D32: EBIT | F32: ₹ Cr | H32: =H30+H31 -> 57.46 | I32: =I30+I31 -> 74.9 | J32: =J30+J31 -> 95.42 | K32: =K30+K31 -> 87.18 | L32: =L30+L31 -> 108.53 | M32: =SUM(M30:M31) -> 121.38106 | N32: =SUM(N30:N31) -> 127.7551 | O32: =SUM(O30:O31) -> 134.27327 | P32: =SUM(P30:P31) -> 136.99999 | Q32: =SUM(Q30:Q31) -> 143.52864 | R32: =SUM(R30:R31) -> 150.1086 | S32: =SUM(S30:S31) -> 151.90028 | T32: =SUM(T30:T31) -> 158.45086 | ... V32: =SUM(V30:V31) -> 165.91633
D33: Interest | F33: ₹ Cr | H33: =-'Historical '!J13 -> -13.77 | I33: =-'Historical '!K13 -> -19.08 | J33: =-'Historical '!L13 -> -28.94 | K33: =-'Historical '!M13 -> -42.06 | L33: =-'Historical '!N13 -> -48.5 | M33: =M121 -> -67.958686 | N33: =N121 -> -67.958686 | O33: =O121 -> -67.958686 | P33: =P121 -> -67.958686 | Q33: =Q121 -> -67.958686 | R33: =R121 -> -67.958686 | S33: =S121 -> -67.958686 | T33: =T121 -> -67.958686 | ... V33: =V121 -> -67.958686
D34: Other Income (Expenses) | F34: ₹ Cr | H34: =SUM('Historical '!J7,'Historical '!J18,'Historical '!J19) -> 0.52 | I34: =SUM('Historical '!K7,'Historical '!K18,'Historical '!K19) -> 1.25 | J34: =SUM('Historical '!L7,'Historical '!L18,'Historical '!L19) -> 4.55 | K34: =SUM('Historical '!M7,'Historical '!M18,'Historical '!M19) -> 7.65 | L34: =SUM('Historical '!N7,'Historical '!N18,'Historical '!N19) -> -9.87 | M34: =M14*M24 -> 5.7426923 | N34: =N14*N24 -> 6.1205614 | O34: =O14*O24 -> 6.4991304 | P34: =P14*P24 -> 6.8769955 | Q34: =Q14*Q24 -> 7.25284 | R34: =R14*R24 -> 7.6254422 | S34: =S14*S24 -> 7.9936816 | T34: =T14*T24 -> 8.3565422 | ... V34: =V14*V24 -> 9.0625943
D35: Earnings before Tax | F35: ₹ Cr | H35: =SUM(H32:H34) -> 44.21 | I35: =SUM(I32:I34) -> 57.07 | J35: =SUM(J32:J34) -> 71.03 | K35: =SUM(K32:K34) -> 52.77 | L35: =SUM(L32:L34) -> 50.16 | M35: =SUM(M32:M34) -> 59.16507 | N35: =SUM(N32:N34) -> 65.916979 | O35: =SUM(O32:O34) -> 72.813717 | ... V35: =SUM(V32:V34) -> 107.02024
D36: Taxes | F36: ₹ Cr | H36: =-SUM('Historical '!J22:J23) -> -12.88 | I36: =-SUM('Historical '!K22:K23) -> -12.44 | J36: =-SUM('Historical '!L22:L23) -> -21.06 | K36: =-SUM('Historical '!M22:M23) -> -17.12 | L36: =-SUM('Historical '!N22:N23) -> -15.33 | M36: =-M15*M35 -> -18.200478 | N36: =-N15*N35 -> -20.277513 | O36: =-O15*O35 -> -22.399102 | P36: =-P15*P35 -> -23.505976 | Q36: =-Q15*Q35 -> -25.64376 | R36: =-R15*R35 -> -27.796427 | S36: =-S15*S35 -> -28.649056 | T36: =-T15*T35 -> -30.803437 | ... V36: =-V15*V35 -> -33.563903
D37: Net Earnings | F37: ₹ Cr | H37: =H35+H36 -> 31.33 | I37: =I35+I36 -> 44.63 | J37: =J35+J36 -> 49.97 | K37: =K35+K36 -> 35.65 | L37: =L35+L36 -> 34.83 | M37: =SUM(M35:M36) -> 40.964593 | N37: =SUM(N35:N36) -> 45.639465 | O37: =SUM(O35:O36) -> 50.414615 | P37: =SUM(P35:P36) -> 52.412323 | Q37: =SUM(Q35:Q36) -> 57.179035 | R37: =SUM(R35:R36) -> 61.978931 | S37: =SUM(S35:S36) -> 63.286221 | T37: =SUM(T35:T36) -> 68.045284 | ... V37: =SUM(V35:V36) -> 73.456337
A39: Balance Sheet
B40: Assets
C41: Current Assets:
D42: Cash | F42: ₹ Cr | H42: ='Historical '!J46 -> 0.51 | I42: ='Historical '!K46 -> 32.8 | J42: ='Historical '!L46 -> 18.22 | K42: ='Historical '!M46 -> 12.23 | L42: ='Historical '!N46 -> 4.96 | M42: =M98 -> -177.24596 | N42: =N98 -> -237.30722 | O42: =O98 -> -290.39137 | P42: =P98 -> -334.98239 | Q42: =Q98 -> -372.49914 | R42: =R98 -> -402.96396 | S42: =S98 -> -424.5806 | T42: =T98 -> -439.2512 | ... V42: =V98 -> -446.00253
D43: Bank Deposits | F43: ₹ Cr | H43: ='Historical '!J47 -> 0.7 | I43: ='Historical '!K47 -> 12.42 | J43: ='Historical '!L47 -> 2.48 | K43: ='Historical '!M47 -> 0.26
...

Sheet Ratio Analysis
A1: =Model!A1 -> Neogen Chemicals Limited
A2: Ratios and their Interpretations
A4: Ratio Analysis
B5: Particulars | D5: 2021 | E5: =D5+1 -> 2022 | F5: =E5+1 -> 2023 | G5: =F5+1 -> 2024 | H5: =G5+1 -> 2025 | I5: =H5+1 -> 2026 | J5: =I5+1 -> 2027 | K5: =J5+1 -> 2028 | L5: =K5+1 -> 2029 | ... R5: =Q5+1 -> 2035 | S5: Trend | U5: Interpretation of ratios
D6: Audited | E6: Audited | F6: Audited | G6: Audited | H6: Audited | I6: Estimated | J6: Estimated | K6: Estimated | L6: Estimated | M6: Estimated | N6: Estimated | O6: Estimated | P6: Estimated | Q6: Estimated | R6: Estimated
B8: Profitability Ratios
B9: Gross Margin | D9: =Model!H26/Model!H24 -> 0.41253233 | E9: =Model!I26/Model!I24 -> 0.43566957 | F9: =Model!J26/Model!J24 -> 0.43380746 | G9: =Model!K26/Model!K24 -> 0.44620441 | H9: =Model!L26/Model!L24 -> 0.45591337 | I9: =Model!M26/Model!M24 -> 0.43682543 | J9: =Model!N26/Model!N24 -> 0.43682543 | K9: =Model!O26/Model!O24 -> 0.43682543 | ... R9: =Model!V26/Model!V24 -> 0.43682543 | U9: Gross margin improved from 41.25% in FY21 to 45.59% in FY25, reflecting better product mix, improved pricing power, and operating efficiencies in the specialty chemicals segment. The increase indicates the company’s ability to manage raw material costs while maintaining healthy realization from customers. However, from FY26 onwards, the margin is projected to stabilize at 43.68%, suggesting a normalized margin environment after peak expansion years. The stable forecast assumes balanced raw material prices, steady demand, and no major pricing disruptions. Overall, the trend reflects strong core profitability and disciplined cost management, supporting long-term earnings quality and operational sustainability across the forecast period.
B10: EBITDA Margin | D10: =Model!H30/Model!H24 -> 0.19131417 | E10: =Model!I30/Model!I24 -> 0.17771165 | F10: =Model!J30/Model!J24 -> 0.16266869 | G10: =Model!K30/Model!K24 -> 0.15933803 | H10: =Model!L30/Model!L24 -> 0.17531766 | I10: =Model!M30/Model!M24 -> 0.17327004 | J10: =Model!N30/Model!N24 -> 0.17327004 | K10: =Model!O30/Model!O24 -> 0.17327004 | ... R10: =Model!V30/Model!V24 -> 0.17327004 | U10: EBITDA margin declined from 19.13% in FY21 to 15.93% in FY24, primarily due to higher raw material costs, inflationary pressure, increased operating expenses, and margin compression across the business. However, the margin recovered to 17.53% in FY25, indicating improvement in operational efficiency, better product mix, and partial normalization of input costs. From FY26 onwards, EBITDA margin is projected to stabilize at 17.33%, reflecting a steady-state operating environment and management’s expectation of sustainable profitability. The stable margin assumption suggests disciplined cost control, balanced pricing strategy, and consistent operating leverage, supporting long-term cash flow generation and earnings stability across the forecast period.
B11: Operating Margin | D11: =Model!H32/Model!H24 -> 0.17080348 | E11: =Model!I32/Model!I24 -> 0.15371986 | F11: =Model!J32/Model!J24 -> 0.13905972 | G11: =Model!K32/Model!K24 -> 0.12622526 | H11: =Model!L32/Model!L24 -> 0.13957765 | I11: =Model!M32/Model!M24 -> 0.1458926 | J11: =Model!N32/Model!N24 -> 0.14407375 | K11: =Model!O32/Model!O24 -> 0.14260415 | ... R11: =Model!V32/Model!V24 -> 0.12636723 | U11: Operating margin declined from 17.08% in FY21 to 12.62% in FY24, mainly due to rising raw material costs, higher employee and operational expenses, and pressure on overall operating efficiency. The margin improved to 13.96% in FY25, reflecting gradual recovery supported by better cost management, improved capacity utilization, and stabilization in input prices. During the forecast period, operating margin is expected to moderate gradually from 14.59% in FY26 to 12.64% in FY35. The decline reflects normalization of margins, competitive pricing pressure, and higher depreciation and operating costs associated with future expansion. Overall, the company is expected to maintain stable operating profitability despite moderate long-term margin compression.
B12: Pretax Margin | D12: =Model!H35/Model!H24 -> 0.13141702 | E12: =Model!I35/Model!I24 -> 0.11712673 | F12: =Model!J35/Model!J24 -> 0.10351511 | G12: =Model!K35/Model!K24 -> 0.076404071 | H12: =Model!L35/Model!L24 -> 0.064509491 | I12: =Model!M35/Model!M24 -> 0.071112787 | J12: =Model!N35/Model!N24 -> 0.074336804 | K12: =Model!O35/Model!O24 -> 0.077331389 | ... R12: =Model!V35/Model!V24 -> 0.081510065 | U12: Pretax margin declined significantly from 13.14% in FY21 to 6.45% in FY25, indicating pressure on overall profitability due to rising finance costs, higher depreciation, increased operating expenses, and margin compression across the business. The sharp decline suggests that earnings growth was impacted despite revenue expansion. However, from FY26 onwards, pretax margin is expected to gradually improve and stabilize in the range of 7%–8%, supported by operating recovery, better utilization of expanded capacity, and normalization of cost structures. The projected improvement reflects management’s focus on profitability enhancement and operational efficiency. Overall, the trend indicates gradual earnings stabilization with moderate long-term profitability improvement across the forecast period.
B13: Effective Tax rate | D13: =-Model!H36/Model!H35 -> 0.2913368 | E13: =-Model!I36/Model!I35 -> 0.21797792 | F13: =-Model!J36/Model!J35 -> 0.29649444 | G13: =-Model!K36/Model!K35 -> 0.32442676 | H13: =-Model!L36/Model!L35 -> 0.30562201 | I13: =-Model!M36/Model!M35 -> 0.30762201 | J13: =-Model!N36/Model!N35 -> 0.30762201 | K13: =-Model!O36/Model!O35 -> 0.30762201 | ... R13: =-Model!V36/Model!V35 -> 0.31362201 | U13: The effective tax rate remained volatile during the historical period, moving from 29.13% in FY21 to 21.80% in FY22, before increasing to 32.44% in FY24 and moderating to 30.56% in FY25. The fluctuations were primarily driven by changes in taxable income, deferred tax adjustments, tax incentives, and variations in the company’s earnings mix across business segments. During the forecast period, the effective tax rate is expected to remain broadly stable in the range of 30.7%–31.4%, reflecting a normalized tax structure and consistent profitability assumptions. The stable tax assumption supports predictability in net earnings and cash flow generation while aligning with the company’s long-term operational outlook and prevailing corporate tax framework.
B14: Net Margin | D14: =Model!H37/Model!H24 -> 0.093130406 | E14: =Model!I37/Model!I24 -> 0.09159569 | F14: =Model!J37/Model!J24 -> 0.072823457 | G14: =Model!K37/Model!K24 -> 0.051616546 | H14: =Model!L37/Model!L24 -> 0.044793971 | I14: =Model!M37/Model!M24 -> 0.049236928 | J14: =Model!N37/Model!N24 -> 0.051469167 | K14: =Model!O37/Model!O24 -> 0.053542551 | ... R14: =Model!V37/Model!V24 -> 0.055946715 | U14: Net margin declined from 9.31% in FY21 to 4.48% in FY25, reflecting pressure on overall profitability due to rising operating costs, higher depreciation, increased finance expenses, and elevated tax outflows. The decline indicates that growth in revenue was not fully translated into bottom-line earnings during the period. However, from FY26 onwards, net margin is projected to gradually improve and stabilize in the range of 5%–6%, supported by better operational efficiency, improved capacity utilization, and normalization of cost structures. The recovery also reflects expected stability in finance costs and tax rates. Overall, the projected trend indicates gradual improvement in earnings quality and long-term profitability sustainability.
B16: DuPont/Earning Power
B17: Asset Turnover | E17: =Model!I24/AVERAGE(Model!H52:I52) -> 0.7547126 | F17: =Model!J24/AVERAGE(Model!I52:J52) -> 0.74059124 | G17: =Model!K24/AVERAGE(Model!J52:K52) -> 0.54919688 | H17: =Model!L24/AVERAGE(Model!K52:L52) -> 0.48465583 | I17: =Model!M24/AVERAGE(Model!L52:M52) -> 0.48055155 | J17: =Model!N24/AVERAGE(Model!M52:N52) -> 0.50928805 | K17: =Model!O24/AVERAGE(Model!N52:O52) -> 0.52463242 | L17: =Model!P24/AVERAGE(Model!O52:P52) -> 0.53819632 | ... R17: =Model!V24/AVERAGE(Model!U52:V52) -> 0.58261175 | U17: Asset turnover declined from 75.47% in FY22 to 48.06% in FY26, indicating lower efficiency in utilizing assets to generate revenue. The decline was primarily driven by significant capital expenditure, capacity expansion, and growth in fixed assets ahead of revenue realization. This suggests that the company invested aggressively for future growth, while asset monetization remained gradual during the initial years. However, from FY27 onwards, asset turnover is projected to improve steadily and reach 58.26% by FY35, supported by higher capacity utilization, revenue growth, and improved operational efficiency. The improving trend indicates gradual optimization of the asset base and better productivity from long-term strategic investments across the forecast period.
B18: Pre tax ROA | E18: =Model!I35/AVERAGE(Model!H52:I52) -> 0.08839702 | F18: =Model!J35/AVERAGE(Model!I52:J52) -> 0.076662385 | G18: =Model!K35/AVERAGE(Model!J52:K52) -> 0.041960878 | H18: =Model!L35/AVERAGE(Model!K52:L52) -> 0.031264901 | I18: =Model!M35/AVERAGE(Model!L52:M52) -> 0.03417336 | J18: =Model!N35/AVERAGE(Model!M52:N52) -> 0.037858846 | K18: =Model!O35/AVERAGE(Model!N52:O52) -> 0.040570554 | L18: =Model!P35/AVERAGE(Model!O52:P52) -> 0.041009673 | ... R18: =Model!V35/AVERAGE(Model!U52:V52) -> 0.047488722 | U18: Pre-tax ROA declined from 8.84% in FY22 to 3.13% in FY25, reflecting reduced efficiency in generating earnings from the company’s asset base. The decline was primarily driven by lower pretax profitability, rising operating and finance costs, and significant capital expansion that increased total assets faster than earnings growth. The trend indicates temporary pressure on asset productivity during the expansion phase. However, from FY26 onwards, pre-tax ROA is projected to gradually improve and reach 4.75% by FY35, supported by better utilization of expanded capacities, operational recovery, and steady improvement in pretax earnings. The improving trend reflects gradual normalization in returns and enhanced efficiency in deploying long-term assets.
B19: Pre Tax ROE | E19: =Model!I35/AVERAGE(Model!H65:I65) -> 0.1834311 | F19: =Model!J35/AVERAGE(Model!I65:J65) -> 0.15411821 | G19: =Model!K35/AVERAGE(Model!J65:K65) -> 0.084920463 | H19: =Model!L35/AVERAGE(Model!K65:L65) -> 0.064735945 | I19: =Model!M35/AVERAGE(Model!L65:M65) -> 0.073338741 | J19: =Model!N35/AVERAGE(Model!M65:N65) -> 0.078155283 | K19: =Model!O35/AVERAGE(Model!N65:O65) -> 0.082360483 | L19: =Model!P35/AVERAGE(Model!O65:P65) -> 0.081841245 | ... R19: =Model!V35/AVERAGE(Model!U65:V65) -> 0.085294522 | U19: Pre-tax ROE declined significantly from 18.34% in FY22 to 6.47% in FY25, indicating lower profitability generated on shareholders’ equity during the period. The decline was primarily driven by reduced pretax earnings, margin compression, rising finance costs, and expansion in the equity base through retained earnings and capital investments. This reflects temporary pressure on shareholder returns during the company’s growth and expansion phase. However, from FY26 onwards, pre-tax ROE is projected to gradually improve and stabilize in the range of 7%–9%, supported by recovery in profitability, improved operational efficiency, and better utilization of invested capital. The improving trend indicates gradual strengthening of earnings generation capability and long-term shareholder value creation.
B20: Tax Complement | D20: =1-Model!H15 -> 0.7086632 | E20: =1-Model!I15 -> 0.78202208 | F20: =1-Model!J15 -> 0.70350556 | G20: =1-Model!K15 -> 0.67557324 | H20: =1-Model!L15 -> 0.69437799 | I20: =1-Model!M15 -> 0.69237799 | J20: =1-Model!N15 -> 0.69237799 | K20: =1-Model!O15 -> 0.69237799 | ... R20: =1-Model!V15 -> 0.68637799 | U20: Tax complement remained relatively stable during the historical and forecast period, fluctuating between 0.68 and 0.78. The ratio declined from 0.78 in FY22 to 0.68 in FY24, reflecting an increase in the effective tax burden during the period. From FY25 onwards, the tax complement stabilized at approximately 0.69, indicating consistency in the company’s effective tax structure and normalized tax assumptions. The stable trend suggests limited volatility in tax outflows and improved predictability in post-tax earnings generation. Overall, the ratio reflects a balanced tax environment and supports stability in net profitability, cash flow planning, and long-term financial projections across the forecast period.
B21: ROE | E21: =Model!I37/AVERAGE(Model!H65:I65) -> 0.14344717 | F21: =Model!J37/AVERAGE(Model!I65:J65) -> 0.10842302 | G21: =Model!K37/AVERAGE(Model!J65:K65) -> 0.057369992 | H21: =Model!L37/AVERAGE(Model!K65:L65) -> 0.044951216 | I21: =Model!M37/AVERAGE(Model!L65:M65) -> 0.05077813 | J21: =Model!N37/AVERAGE(Model!M65:N65) -> 0.054112998 | K21: =Model!O37/AVERAGE(Model!N65:O65) -> 0.057024586 | L21: =Model!P37/AVERAGE(Model!O65:P65) -> 0.056501394 | ... R21: =Model!V37/AVERAGE(Model!U65:V65) -> 0.058544282 | U21: ROE declined significantly from 14.34% in FY22 to 4.50% in FY25, indicating lower profitability generated from shareholders’ equity during the period. The decline was primarily driven by margin compression, higher operating and finance costs, increased depreciation, and expansion in the equity base through retained earnings and capital investments. This reflects temporary pressure on shareholder returns during the company’s investment and expansion phase. However, from FY26 onwards, ROE is projected to gradually improve and stabilize in the range of 5%–6%, supported by recovery in net profitability, improved operational efficiency, and better utilization of capital. The gradual improvement indicates stabilization in earnings generation and moderate long-term shareholder value creation.
B22: Equity Retention | D22: =1-Model!H16 -> 0.85094159 | E22: =1-Model!I16 -> 0.88236612 | F22: =1-Model!J16 -> 0.86271763 | G22: =1-Model!K16 -> 0.79018233 | H22: =1-Model!L16 -> 0.84840655 | I22: =1-Model!M16 -> 0.84692284 | J22: =1-Model!N16 -> 0.84692284 | K22: =1-Model!O16 -> 0.84692284 | ... R22: =1-Model!V16 -> 0.84692284 | U22: Equity retention ratio remained strong and relatively stable during the period, ranging between 0.79 and 0.88. The ratio declined to 0.79 in FY24, indicating comparatively higher dividend distribution or lower earnings retention during the year. However, from FY25 onwards, the retention ratio stabilized at approximately 0.85, reflecting the company’s consistent strategy of retaining a significant portion of earnings to support future growth, capital expenditure, and business expansion. The high retention level indicates management’s focus on reinvestment rather than aggressive dividend payouts. Overall, the stable retention ratio supports long-term growth potential, internal funding capacity, and financial flexibility while strengthening the company’s ability to finance expansion through retained earnings.
B23: Reinvestment Rate | E23: =(Model!I112-Model!I113+Model!I108)/(Model!I32*(1-Model!$H$129)) -> 0.13991989 | F23: =(Model!J112-Model!J113+Model!J108)/(Model!J32*(1-Model!$H$129)) -> -0.24048068 | G23: =(Model!K112-Model!K113+Model!K108)/(Model!K32*(1-Model!$H$129)) -> 2.117917 | H23: =(Model!L112-Model!L113+Model!L108)/(Model!L32*(1-Model!$H$129)) -> 0.93418103 | I23: =(Model!M112-Model!M113+Model!M108)/(Model!M32*(1-Model!$H$129)) -> -0.2042033 | J23: =(Model!N112-Model!N113+Model!N108)/(Model!N32*(1-Model!$H$129)) -> 1.0395476 | K23: =(Model!O112-Model!O113+Model!O108)/(Model!O32*(1-Model!$H$129)) -> 1.018307 | L23: =(Model!P112-Model!P113+Model!P108)/(Model!P32*(1-Model!$H$129)) -> 1.0643289 | ... R23: =(Model!V112-Model!V113+Model!V108)/(Model!V32*(1-Model!$H$129)) -> 1.1029643 | U23: Reinvestment rate remained highly volatile during the historical period, moving from 13.99% in FY22 to negative 24.05% in FY23, before sharply increasing to 211.79% in FY24. The volatility reflects fluctuations in capital expenditure, working capital requirements, and operating profitability during the company’s expansion phase. Negative reinvestment in certain years indicates lower reinvestment relative to earnings, while ratios above 100% suggest aggressive investment beyond internally generated profits, likely funded through debt or external capital. During the forecast period, reinvestment rate is projected to remain above 100%, reflecting continued capacity expansion, strategic growth investments, and management’s focus on long-term business scaling. The trend indicates an aggressive growth-oriented capital allocation strategy.
B25: Liquidity Ratio
B26: Quick ratio | D26: =(Model!H42+Model!H43+Model!H44+Model!H46)/(Model!H56+Model!H57) -> 1.3687466 | E26: =(Model!I42+Model!I43+Model!I44+Model!I46)/(Model!I56+Model!I57) -> 2.0991543 | F26: =(Model!J42+Model!J43+Model!J44+Model!J46)/(Model!J56+Model!J57) -> 2.0545835 | G26: =(Model!K42+Model!K43+Model!K44+Model!K46)/(Model!K56+Model!K57) -> 1.5571079 | H26: =(Model!L42+Model!L43+Model!L44+Model!L46)/(Model!L56+Model!L57) -> 2.0467611 | I26: =(Model!M42+Model!M43+Model!M44+Model!M46)/(Model!M56+Model!M57) -> 1.9877053 | J26: =(Model!N42+Model!N43+Model!N44+Model!N46)/(Model!N56+Model!N57) -> 1.7387561 | K26: =(Model!O42+Model!O43+Model!O44+Model!O46)/(Model!O56+Model!O57) -> 1.5350004 | ... R26: =(Model!V42+Model!V43+Model!V44+Model!V46)/(Model!V56+Model!V57) -> 1.0469413 | U26: Quick ratio improved from 1.37 in FY21 to 2.10 in FY22, indicating stronger short-term liquidity and improved ability to meet current obligations using liquid assets. The ratio remained healthy during the historical period, supported by higher cash balances, receivables, and efficient working capital management. However, from FY26 onwards, the quick ratio is projected to gradually decline and stabilize near 1.0x by FY35. The decline reflects increasing working capital utilization, expansion-related funding requirements, and gradual normalization of liquidity levels as operations scale. Despite the moderation, the ratio remains above or near the minimum acceptable level, indicating that the company is expected to maintain adequate short-term liquidity and financial flexibility throughout the forecast period.
B27: Current ratio | D27: =SUM(Model!H42:H46)/SUM(Model!H56:H570) -> 0.0016835116 | E27: =SUM(Model!I42:I46)/SUM(Model!I56:I570) -> 0.0094173416 | F27: =SUM(Model!J42:J46)/SUM(Model!J56:J570) -> 0.011107912 | G27: =SUM(Model!K42:K46)/SUM(Model!K56:K570) -> 0.012544379 | H27: =SUM(Model!L42:L46)/SUM(Model!L56:L570) -> 0.012903714 | I27: =SUM(Model!M42:M46)/SUM(Model!M56:M570) -> 0.014169777 | J27: =SUM(Model!N42:N46)/SUM(Model!N56:N570) -> 0.013106568 | K27: =SUM(Model!O42:O46)/SUM(Model!O56:O570) -> 0.015206298 | ... R27: =SUM(Model!V42:V46)/SUM(Model!V56:V570) -> 0.015752943 | U27: Current ratio remained extremely low during the historical and forecast period, increasing marginally from 0.002 in FY21 to 0.016 by FY35. The consistently low ratio indicates that current liabilities significantly exceed current assets, reflecting pressure on short-term liquidity and working capital coverage. The gradual improvement over the forecast period suggests modest strengthening in liquidity position supported by incremental growth in current assets and operational cash flows. However, the ratio remaining substantially below 1.0x indicates continued dependence on efficient cash flow management, short-term funding support, and working capital discipline to meet near-term obligations. Overall, the trend reflects a constrained liquidity position and highlights the importance of maintaining stable operational cash generation.
B28: Cash Cycle (Days) | D28: =D37+D39-D41 -> 173.78378 | E28: =E37+E39-E41 -> 209.07381 | F28: =F37+F39-F41 -> 222.5186 | G28: =G37+G39-G41 -> 375.82974 | H28: =H37+H39-H41 -> 133.62198 | I28: =I37+I39-I41 -> 222.96558 | J28: =J37+J39-J41 -> 222.96558 | K28: =K37+K39-K41 -> 222.96558 | ... R28: =R37+R39-R41 -> 222.96558 | U28: Cash conversion cycle increased from 173.78 days in FY21 to 375.83 days in FY24, indicating significant pressure on working capital efficiency during the period. The increase was primarily driven by higher inventory holding periods, slower receivable collections, and expansion-related operational buildup. However, the cycle improved sharply to 133.62 days in FY25, reflecting better working capital management, improved collection efficiency, and normalization in inventory levels. From FY26 onwards, the cash cycle is projected to stabilize at approximately 223 days, indicating a consistent operating cycle aligned with the company’s business model and industry dynamics. The stable trend suggests predictable working capital requirements, although the relatively high cycle indicates continued capital blockage within operations and inventory management.
B30: Leverage
B31: Asset/Equity | D31: =Model!H52/Model!H65 -> 2.6881591 | E31: =Model!I52/Model!I65 -> 1.819643 | F31: =Model!J52/Model!J65 -> 2.1839509 | G31: =Model!K52/Model!K65 -> 1.9221613 | H31: =Model!L52/Model!L65 -> 2.213494 | I31: =Model!M52/Model!M65 -> 2.0815028 | J31: =Model!N52/Model!N65 -> 2.0480366 | K31: =Model!O52/Model!O65 -> 2.0129226 | ... R31: =Model!V52/Model!V65 -> 1.7814922 | U31: The asset-to-equity ratio declined from 2.69x in FY21 to 1.78x by FY35, indicating gradual reduction in financial leverage over the period. The historical fluctuations reflect changes in debt levels, capital expenditure funding, and growth in shareholders’ equity through retained earnings. The decline in the ratio during the forecast period suggests that the company is expected to rely relatively less on external liabilities and maintain a stronger equity base to support future operations and expansion. This indicates improving balance sheet strength and lower financial risk over time. Overall, the trend reflects a gradual shift toward a more conservative capital structure, supported by internal accruals, earnings retention, and disciplined long-term financial management.
B32: Debt/Equity | D32: =Model!H59/Model!H65 -> 1.1031638 | E32: =Model!I59/Model!I65 -> 0.45014115 | F32: =Model!J59/Model!J65 -> 0.75066318 | G32: =Model!K59/Model!K65 -> 0.51760512 | H32: =Model!L59/Model!L65 -> 0.71706001 | I32: =Model!M59/Model!M65 -> 0.68687185 | J32: =Model!N59/Model!N65 -> 0.65609801 | K32: =Model!O59/Model!O65 -> 0.6251586 | ... R32: =Model!V59/Model!V65 -> 0.44021712 | U32: Debt-to-equity ratio declined from 1.10x in FY21 to 0.44x by FY35, indicating gradual deleveraging and improvement in the company’s capital structure over the forecast period. Historical fluctuations were primarily driven by expansion-related borrowings, capital expenditure funding requirements, and growth in shareholders’ equity. The elevated ratio in certain years reflects the company’s dependence on debt financing during its expansion phase. However, the steady decline from FY26 onwards suggests repayment of borrowings, stronger internal accrual generation, and increasing equity support through retained earnings. The improving trend indicates lower financial risk, reduced dependence on external debt, and strengthening balance sheet stability, which supports long-term financial flexibility and sustainable growth.
B33: % LT Debt to Total Capital | D33: =Model!H59/SUM(Model!H59,Model!H65) -> 0.52452585 | E33: =Model!I59/SUM(Model!I59,Model!I65) -> 0.31041196 | F33: =Model!J59/SUM(Model!J59,Model!J65) -> 0.4287879 | G33: =Model!K59/SUM(Model!K59,Model!K65) -> 0.34106706 | H33: =Model!L59/SUM(Model!L59,Model!L65) -> 0.41760917 | I33: =Model!M59/SUM(Model!M59,Model!M65) -> 0.40718674 | J33: =Model!N59/SUM(Model!N59,Model!N65) -> 0.396171 | K33: =Model!O59/SUM(Model!O59,Model!O65) -> 0.38467544 | ... R33: =Model!V59/SUM(Model!V59,Model!V65) -> 0.30566025 | U33: Long-term debt to total capital declined from 52% in FY21 to 31% by FY35, indicating gradual improvement in the company’s capital structure and reduced reliance on long-term borrowings. Historical fluctuations were primarily driven by debt-funded capital expenditure, expansion initiatives, and changes in the equity base. The higher ratio during certain years reflects increased leverage used to finance growth projects and capacity additions. However, the consistent decline during the forecast period suggests gradual repayment of long-term debt and stronger contribution from shareholders’ equity and retained earnings. The improving trend indicates lower financial leverage, reduced refinancing risk, and strengthening balance sheet quality, supporting long-term financial stability and improved flexibility for future growth investments.
B35: Operating
B36: A/R Turnover | E36: =Model!I24/AVERAGE(Model!H44:I44) -> 5.1821324 | F36: =Model!J24/AVERAGE(Model!I44:J44) -> 4.7837423 | G36: =Model!K24/AVERAGE(Model!J44:K44) -> 3.0089964 | H36: =Model!L24/AVERAGE(Model!K44:L44) -> 3.2269926 | I36: =Model!M24/AVERAGE(Model!L44:M44) -> 3.8679661 | J36: =Model!N24/AVERAGE(Model!M44:N44) -> 3.7329754 | K36: =Model!O24/AVERAGE(Model!N44:O44) -> 3.7262689 | L36: =Model!P24/AVERAGE(Model!O44:P44) -> 3.7199412 | ... R36: =Model!V24/AVERAGE(Model!U44:V44) -> 3.6888696 | U36: Accounts receivable turnover declined from 5.18x in FY22 to 3.01x in FY24, indicating slower collection efficiency and an increase in credit period extended to customers. The decline suggests that receivables grew faster than revenue during the period, likely due to expansion in business operations, customer mix changes, and higher working capital requirements. However, the ratio improved to 3.87x in FY26 and is projected to stabilize around 3.7x during the forecast period, reflecting normalization in collection cycles and more stable receivable management practices. The stable turnover trend indicates consistent cash collection efficiency, although the lower ratio compared to earlier years suggests relatively longer cash realization cycles and continued working capital intensity.
B37: Avg. A/R Days | D37: =Model!H17 -> 85.225618 | E37: =Model!I17 -> 82.02668 | F37: =Model!J17 -> 94.353814 | G37: =Model!K17 -> 148.86538 | H37: =Model!L17 -> 93.986702 | I37: =Model!M17 -> 100.89164 | J37: =Model!N17 -> 100.89164 | K37: =Model!O17 -> 100.89164 | ... R37: =Model!V17 -> 100.89164 | U37: Average accounts receivable days increased from 82.03 days in FY22 to 148.87 days in FY25, indicating slower customer collections and extended credit periods during the period. The increase suggests higher working capital blockage in receivables, likely driven by business expansion, changes in customer mix, and industry-specific credit practices. However, receivable days improved to 93.99 days in FY26 and are projected to stabilize at approximately 101 days throughout the forecast period. The stabilization reflects management’s expectation of consistent collection efficiency and normalized credit terms. Although the receivable cycle remains relatively high, the stable trend indicates predictable cash conversion patterns and manageable working capital requirements aligned with the company’s operating structure and growth strategy.
B38: Inventory Turnover | E38: =-Model!I25/AVERAGE(Model!H45:I45) -> 1.7819325 | F38: =-Model!J25/AVERAGE(Model!I45:J45) -> 1.593691 | G38: =-Model!K25/AVERAGE(Model!J45:K45) -> 1.1326157 | H38: =-Model!L25/AVERAGE(Model!K45:L45) -> 1.223477 | I38: =-Model!M25/AVERAGE(Model!L45:M45) -> 1.4148118 | J38: =-Model!N25/AVERAGE(Model!M45:N45) -> 1.3687509 | K38: =-Model!O25/AVERAGE(Model!N45:O45) -> 1.3662919 | L38: =-Model!P25/AVERAGE(Model!O45:P45) -> 1.3639718 | ... R38: =-Model!V25/AVERAGE(Model!U45:V45) -> 1.3525789 | U38: Inventory turnover declined from 1.78x in FY22 to 1.13x in FY24, indicating slower movement of inventory and higher inventory holding levels during the period. The decline was primarily driven by expansion-related inventory buildup, higher raw material stocking, and relatively slower conversion of inventory into sales. This reflects increased working capital intensity and temporary pressure on inventory efficiency. However, the ratio improved to 1.41x in FY26 and is projected to stabilize around 1.35x during the forecast period, suggesting normalization in inventory management and operating cycles. The stable trend indicates consistent inventory utilization aligned with production requirements, although the relatively low turnover reflects continued high inventory holding requirements within the company’s business model and industry structure.
B39: Avg. Inventory Days | D39: =Model!H18 -> 210.60036 | E39: =Model!I18 -> 258.30218 | F39: =Model!J18 -> 275.24144 | G39: =Model!K18 -> 364.95229 | H39: =Model!L18 -> 266.70555 | I39: =Model!M18 -> 275.16036 | J39: =Model!N18 -> 275.16036 | K39: =Model!O18 -> 275.16036 | ... R39: =Model!V18 -> 275.16036 | U39: Average inventory days increased from 210.60 days in FY21 to 364.95 days in FY24, indicating slower inventory movement and higher inventory holding during the expansion phase. The increase was primarily driven by higher raw material stocking, capacity expansion, and buildup of finished goods to support future demand and operational continuity. The elevated inventory period reflects significant working capital blockage and lower inventory conversion efficiency during the period. However, inventory days improved to 266.71 days in FY25 and are projected to stabilize at approximately 275 days throughout the forecast period. The stable trend suggests normalized inventory management aligned with the company’s production cycle, although the relatively high inventory holding period indicates continued working capital intensity within operations.
B40: A/P Turnover | E40: =-Model!I25/AVERAGE(Model!H56:I56) -> 3.3337779 | F40: =-Model!J25/AVERAGE(Model!I56:J56) -> 3.0420076 | G40: =-Model!K25/AVERAGE(Model!J56:K56) -> 2.5401959 | H40: =-Model!L25/AVERAGE(Model!K56:L56) -> 2.0748915 | I40: =-Model!M25/AVERAGE(Model!L56:M56) -> 2.038486 | J40: =-Model!N25/AVERAGE(Model!M56:N56) -> 2.4602183 | K40: =-Model!O25/AVERAGE(Model!N56:O56) -> 2.4557983 | L40: =-Model!P25/AVERAGE(Model!O56:P56) -> 2.4516281 | ... R40: =-Model!V25/AVERAGE(Model!U56:V56) -> 2.4311503 | U40: Accounts payable turnover declined from 3.33x in FY22 to 2.04x in FY26, indicating slower payment cycles and increased credit utilization from suppliers during the period. The decline suggests that the company extended payment timelines to manage working capital requirements and support expansion-related operational needs. Lower payable turnover reflects greater dependence on supplier financing as part of the working capital strategy. However, from FY27 onwards, the ratio is projected to stabilize around 2.4x, indicating consistent payment practices and normalized supplier credit terms. The stable trend suggests balanced working capital management and predictable cash outflows, although the relatively lower turnover indicates that the company is expected to continue utilizing trade credit as an important operational funding source.
B41: Avg. A/P Days | D41: =Model!H19 -> 122.0422 | E41: =Model!I19 -> 131.25505 | F41: =Model!J19 -> 147.07665 | G41: =Model!K19 -> 137.98792 | H41: =Model!L19 -> 227.07027 | I41: =Model!M19 -> 153.08642 | J41: =Model!N19 -> 153.08642 | K41: =Model!O19 -> 153.08642 | ... R41: =Model!V19 -> 153.08642 | U41: Average accounts payable days increased from 122.04 days in FY21 to 227.07 days in FY25, indicating that the company extended its payment cycle and utilized higher supplier credit during the period. The increase was primarily driven by working capital optimization efforts, expansion-related funding requirements, and stronger reliance on trade payables to support operations. Higher payable days helped partially offset pressure from elevated receivable and inventory cycles. However, payable days are projected to normalize and stabilize at approximately 153 days from FY26 onwards, reflecting consistent supplier payment practices and balanced working capital management. The stable trend indicates predictable cash outflows and continued use of trade credit as a key operational financing source while maintaining supplier relationship stability.
B42: Fixed Asset Turnover | E42: =Model!I24/AVERAGE(Model!H48:I48) -> 1.8159964 | F42: =Model!J24/AVERAGE(Model!I48:J48) -> 2.0257133 | G42: =Model!K24/AVERAGE(Model!J48:K48) -> 1.4020056 | H42: =Model!L24/AVERAGE(Model!K48:L48) -> 1.3377606 | I42: =Model!M24/AVERAGE(Model!L48:M48) -> 1.3929433 | J42: =Model!N24/AVERAGE(Model!M48:N48) -> 1.3193237 | K42: =Model!O24/AVERAGE(Model!N48:O48) -> 1.2657467 | L42: =Model!P24/AVERAGE(Model!O48:P48) -> 1.2288064 | ... R42: =Model!V24/AVERAGE(Model!U48:V48) -> 1.1685213 | U42: Fixed asset turnover improved from 1.82x in FY22 to 2.03x in FY23, indicating efficient utilization of fixed assets to generate revenue during the period. However, the ratio declined to 1.34x in FY26 and is projected to gradually moderate to 1.17x by FY35. The decline primarily reflects significant capital expenditure, capacity expansion, and growth in the fixed asset base ahead of full revenue realization. This indicates that asset creation has outpaced short-term revenue generation during the expansion phase. The stable ratio in later years suggests gradual normalization in asset utilization and consistent operational efficiency. Overall, the trend reflects a long-term investment-driven growth strategy with moderate pressure on fixed asset productivity during the forecast period.
B43: ROIC | D43: =Model!H37/SUM(Model!H59,Model!H65) -> 0.081397766 | E43: =Model!I37/SUM(Model!I59,Model!I65) -> 0.070067194 | F43: =Model!J37/SUM(Model!J59,Model!J65) -> 0.059154996 | G43: =Model!K37/SUM(Model!K59,Model!K65) -> 0.030897367 | H43: =Model!L37/SUM(Model!L59,Model!L65) -> 0.025696642 | I43: =Model!M37/SUM(Model!M59,Model!M65) -> 0.029468304 | J43: =Model!N37/SUM(Model!N59,Model!N65) -> 0.03194303 | K43: =Model!O37/SUM(Model!O59,Model!O65) -> 0.034261296 | ... R43: =Model!V37/SUM(Model!V59,Model!V65) -> 0.039666247 | U43: ROIC declined from 8.14% in FY21 to 2.57% in FY25, indicating reduced efficiency in generating returns from invested capital during the expansion period. The decline was primarily driven by lower operating profitability, rising capital expenditure, increased working capital intensity, and growth in the invested capital base ahead of full earnings realization. This suggests that the company’s investments have not yet generated proportional returns during the initial expansion phase. However, from FY26 onwards, ROIC is projected to gradually improve and reach approximately 4.0% by FY35, supported by better capacity utilization, operational stabilization, and gradual improvement in profitability. The improving trend reflects expected recovery in capital efficiency and long-term value creation potential from strategic investments.

Sheet Summary
A1: ='Ratio Analysis'!A1 -> Neogen Chemicals Limited
A2: Valuation Summary - Football Field
A4: Valuation Summary - Football Field
K5: Market
H6: Comps | I6: DCF | J6: 52-week hi/lo | K6: Consensus
B7: High | H7: =MAX(Comp!K22:K24) -> 1564.5126 | I7: 1361.204 | J7: =Beta!K7 -> 1744.85 | K7: =MAX(I32:I34) -> 2001
B8: High | H8: =H7 -> 1564.5126 | I8: =I7 -> 1361.204 | J8: =J7 -> 1744.85 | K8: =K7 -> 2001
B9: Low | H9: =MIN(Comp!K22:K24) -> 647.46217 | I9: 692.81231 | J9: =Beta!K6 -> 351.1 | K9: =MIN(I32:I34) -> 1395
B10: Low | H10: =H9 -> 647.46217 | I10: =I9 -> 692.81231 | J10: =J9 -> 351.1 | K10: =K9 -> 1395
A12: Valuation Summary
A31: Broker Analysis | E31: Date | H31: LTP | I31: Target Price
A32: IDBI Capita | E32: 46066 | H32: 1295 | I32: 2001
